10:33:20 - INFO -Started server process [9] (server.py:75)
10:33:20 - INFO -Waiting for application startup. (on.py:45)
10:33:20 - INFO -Application startup complete. (on.py:59)
10:34:22 - INFO -172.19.0.19:51352 - "GET /api_payments?bin=170340012106&start_date=2000-01-01 HTTP/1.1" 200 (httptools_impl.py:437)
10:34:22 - INFO -172.19.0.19:51346 - "GET /api_goszakup?iin_bin=170340012106 HTTP/1.1" 200 (httptools_impl.py:437)
10:34:23 - INFO -172.19.0.19:51366 - "GET /elicense?bin=170340012106 HTTP/1.1" 200 (httptools_impl.py:437)
10:34:29 - INFO -172.19.0.19:51354 - "GET /api_goszakup_unrelaible?iin_bin=170340012106 HTTP/1.1" 200 (httptools_impl.py:437)
10:43:13 - INFO -Started server process [9] (server.py:75)
10:43:13 - INFO -Waiting for application startup. (on.py:45)
10:43:13 - INFO -Application startup complete. (on.py:59)
10:43:17 - INFO -172.19.0.19:55222 - "GET /api_payments?bin=170340012106&start_date=2000-01-01 HTTP/1.1" 200 (httptools_impl.py:437)
10:43:17 - INFO -172.19.0.19:55192 - "GET /api_goszakup?iin_bin=170340012106 HTTP/1.1" 200 (httptools_impl.py:437)
10:43:17 - INFO -172.19.0.19:55234 - "GET /api_goszakup?iin_bin=170340012106 HTTP/1.1" 200 (httptools_impl.py:437)
10:43:17 - INFO -172.19.0.19:55248 - "GET /api_payments?bin=170340012106&start_date=2000-01-01 HTTP/1.1" 200 (httptools_impl.py:437)
10:43:18 - INFO -172.19.0.19:55232 - "GET /elicense?bin=170340012106 HTTP/1.1" 200 (httptools_impl.py:437)
10:43:18 - INFO -172.19.0.19:55206 - "GET /api_goszakup_unrelaible?iin_bin=170340012106 HTTP/1.1" 200 (httptools_impl.py:437)
10:43:18 - INFO -172.19.0.19:55264 - "GET /api_goszakup_unrelaible?iin_bin=170340012106 HTTP/1.1" 200 (httptools_impl.py:437)
10:43:22 - INFO -172.19.0.19:55236 - "GET /elicense?bin=170340012106 HTTP/1.1" 200 (httptools_impl.py:437)
10:44:11 - INFO -172.19.0.19:44830 - "GET /api_goszakup?iin_bin=170340012106 HTTP/1.1" 200 (httptools_impl.py:437)
10:44:11 - INFO -172.19.0.19:44834 - "GET /api_payments?bin=170340012106&start_date=2000-01-01 HTTP/1.1" 200 (httptools_impl.py:437)
10:44:11 - INFO -172.19.0.19:44838 - "GET /elicense?bin=170340012106 HTTP/1.1" 200 (httptools_impl.py:437)
10:44:12 - INFO -172.19.0.19:44824 - "GET /api_goszakup_unrelaible?iin_bin=170340012106 HTTP/1.1" 200 (httptools_impl.py:437)
10:45:06 - INFO -Started server process [9] (server.py:75)
10:45:06 - INFO -Waiting for application startup. (on.py:45)
10:45:06 - INFO -Application startup complete. (on.py:59)
10:45:29 - INFO -Started server process [9] (server.py:75)
10:45:29 - INFO -Waiting for application startup. (on.py:45)
10:45:29 - INFO -Application startup complete. (on.py:59)
10:45:34 - INFO -172.19.0.6:43510 - "GET /api_payments?bin=170340012106&start_date=2000-01-01 HTTP/1.1" 200 (httptools_impl.py:437)
10:45:34 - INFO -172.19.0.6:43500 - "GET /api_goszakup?iin_bin=170340012106 HTTP/1.1" 200 (httptools_impl.py:437)
10:45:35 - INFO -172.19.0.6:43518 - "GET /elicense?bin=170340012106 HTTP/1.1" 200 (httptools_impl.py:437)
10:45:35 - INFO -172.19.0.6:43522 - "GET /api_goszakup_unrelaible?iin_bin=170340012106 HTTP/1.1" 200 (httptools_impl.py:437)
10:46:51 - INFO -172.19.0.6:45100 - "GET /api_goszakup?iin_bin=170340012106 HTTP/1.1" 200 (httptools_impl.py:437)
10:46:51 - INFO -172.19.0.6:45138 - "GET /api_payments?bin=170340012106&start_date=2000-01-01 HTTP/1.1" 200 (httptools_impl.py:437)
10:46:51 - INFO -172.19.0.6:45126 - "GET /elicense?bin=170340012106 HTTP/1.1" 200 (httptools_impl.py:437)
10:46:52 - INFO -172.19.0.6:45102 - "GET /api_goszakup_unrelaible?iin_bin=170340012106 HTTP/1.1" 200 (httptools_impl.py:437)
10:49:46 - INFO -Started server process [9] (server.py:75)
10:49:46 - INFO -Waiting for application startup. (on.py:45)
10:49:46 - INFO -Application startup complete. (on.py:59)
10:53:29 - INFO -Started server process [9] (server.py:75)
10:53:29 - INFO -Waiting for application startup. (on.py:45)
10:53:29 - INFO -Application startup complete. (on.py:59)
10:54:13 - INFO -172.19.0.19:58276 - "GET /elicense?bin=170340012106 HTTP/1.1" 500 (httptools_impl.py:437)
10:54:13 - ERROR -Exception in ASGI application
 (httptools_impl.py:375)
Traceback (most recent call last):
  File "/usr/local/lib/python3.10/site-packages/urllib3/connection.py", line 174, in _new_conn
    conn = connection.create_connection(
  File "/usr/local/lib/python3.10/site-packages/urllib3/util/connection.py", line 72, in create_connection
    for res in socket.getaddrinfo(host, port, family, socket.SOCK_STREAM):
  File "/usr/local/lib/python3.10/socket.py", line 955, in getaddrinfo
    for res in _socket.getaddrinfo(host, port, family, type, proto, flags):
socket.gaierror: [Errno -2] Name or service not known

During handling of the above exception, another exception occurred:

Traceback (most recent call last):
  File "/usr/local/lib/python3.10/site-packages/urllib3/connectionpool.py", line 703, in urlopen
    httplib_response = self._make_request(
  File "/usr/local/lib/python3.10/site-packages/urllib3/connectionpool.py", line 386, in _make_request
    self._validate_conn(conn)
  File "/usr/local/lib/python3.10/site-packages/urllib3/connectionpool.py", line 1042, in _validate_conn
    conn.connect()
  File "/usr/local/lib/python3.10/site-packages/urllib3/connection.py", line 358, in connect
    self.sock = conn = self._new_conn()
  File "/usr/local/lib/python3.10/site-packages/urllib3/connection.py", line 186, in _new_conn
    raise NewConnectionError(
urllib3.exceptions.NewConnectionError: <urllib3.connection.HTTPSConnection object at 0x7f9f3b56ae90>: Failed to establish a new connection: [Errno -2] Name or service not known

During handling of the above exception, another exception occurred:

Traceback (most recent call last):
  File "/usr/local/lib/python3.10/site-packages/requests/adapters.py", line 440, in send
    resp = conn.urlopen(
  File "/usr/local/lib/python3.10/site-packages/urllib3/connectionpool.py", line 787, in urlopen
    retries = retries.increment(
  File "/usr/local/lib/python3.10/site-packages/urllib3/util/retry.py", line 592, in increment
    raise MaxRetryError(_pool, url, error or ResponseError(cause))
urllib3.exceptions.MaxRetryError: HTTPSConnectionPool(host='elicense.entry.kz', port=443): Max retries exceeded with url: /api/license?iin_bin=170340012106 (Caused by NewConnectionError('<urllib3.connection.HTTPSConnection object at 0x7f9f3b56ae90>: Failed to establish a new connection: [Errno -2] Name or service not known'))

During handling of the above exception, another exception occurred:

Traceback (most recent call last):
  File "/usr/local/lib/python3.10/site-packages/uvicorn/protocols/http/httptools_impl.py", line 372, in run_asgi
    result = await app(self.scope, self.receive, self.send)
  File "/usr/local/lib/python3.10/site-packages/uvicorn/middleware/proxy_headers.py", line 75, in __call__
    return await self.app(scope, receive, send)
  File "/usr/local/lib/python3.10/site-packages/fastapi/applications.py", line 261, in __call__
    await super().__call__(scope, receive, send)
  File "/usr/local/lib/python3.10/site-packages/starlette/applications.py", line 112, in __call__
    await self.middleware_stack(scope, receive, send)
  File "/usr/local/lib/python3.10/site-packages/starlette/middleware/errors.py", line 181, in __call__
    raise exc
  File "/usr/local/lib/python3.10/site-packages/starlette/middleware/errors.py", line 159, in __call__
    await self.app(scope, receive, _send)
  File "/usr/local/lib/python3.10/site-packages/starlette/middleware/cors.py", line 84, in __call__
    await self.app(scope, receive, send)
  File "/usr/local/lib/python3.10/site-packages/starlette/exceptions.py", line 82, in __call__
    raise exc
  File "/usr/local/lib/python3.10/site-packages/starlette/exceptions.py", line 71, in __call__
    await self.app(scope, receive, sender)
  File "/usr/local/lib/python3.10/site-packages/fastapi/middleware/asyncexitstack.py", line 21, in __call__
    raise e
  File "/usr/local/lib/python3.10/site-packages/fastapi/middleware/asyncexitstack.py", line 18, in __call__
    await self.app(scope, receive, send)
  File "/usr/local/lib/python3.10/site-packages/starlette/routing.py", line 656, in __call__
    await route.handle(scope, receive, send)
  File "/usr/local/lib/python3.10/site-packages/starlette/routing.py", line 259, in handle
    await self.app(scope, receive, send)
  File "/usr/local/lib/python3.10/site-packages/starlette/routing.py", line 61, in app
    response = await func(request)
  File "/usr/local/lib/python3.10/site-packages/fastapi/routing.py", line 227, in app
    raw_response = await run_endpoint_function(
  File "/usr/local/lib/python3.10/site-packages/fastapi/routing.py", line 162, in run_endpoint_function
    return await run_in_threadpool(dependant.call, **values)
  File "/usr/local/lib/python3.10/site-packages/starlette/concurrency.py", line 39, in run_in_threadpool
    return await anyio.to_thread.run_sync(func, *args)
  File "/usr/local/lib/python3.10/site-packages/anyio/to_thread.py", line 31, in run_sync
    return await get_asynclib().run_sync_in_worker_thread(
  File "/usr/local/lib/python3.10/site-packages/anyio/_backends/_asyncio.py", line 937, in run_sync_in_worker_thread
    return await future
  File "/usr/local/lib/python3.10/site-packages/anyio/_backends/_asyncio.py", line 867, in run
    result = context.run(func, *args)
  File "/home/api_app/./main.py", line 99, in elicense
    return elicense_parser(bin)
  File "/home/api_app/./parsers/api_elicense_parser.py", line 14, in elicense_parser
    response = request("GET", url)
  File "/usr/local/lib/python3.10/site-packages/requests/api.py", line 61, in request
    return session.request(method=method, url=url, **kwargs)
  File "/usr/local/lib/python3.10/site-packages/requests/sessions.py", line 529, in request
    resp = self.send(prep, **send_kwargs)
  File "/usr/local/lib/python3.10/site-packages/requests/sessions.py", line 645, in send
    r = adapter.send(request, **kwargs)
  File "/usr/local/lib/python3.10/site-packages/requests/adapters.py", line 519, in send
    raise ConnectionError(e, request=request)
requests.exceptions.ConnectionError: HTTPSConnectionPool(host='elicense.entry.kz', port=443): Max retries exceeded with url: /api/license?iin_bin=170340012106 (Caused by NewConnectionError('<urllib3.connection.HTTPSConnection object at 0x7f9f3b56ae90>: Failed to establish a new connection: [Errno -2] Name or service not known'))
10:54:13 - INFO -172.19.0.19:58278 - "GET /api_payments?bin=170340012106&start_date=2000-01-01 HTTP/1.1" 500 (httptools_impl.py:437)
10:54:13 - ERROR -Exception in ASGI application
 (httptools_impl.py:375)
Traceback (most recent call last):
  File "/usr/local/lib/python3.10/site-packages/urllib3/connection.py", line 174, in _new_conn
    conn = connection.create_connection(
  File "/usr/local/lib/python3.10/site-packages/urllib3/util/connection.py", line 72, in create_connection
    for res in socket.getaddrinfo(host, port, family, socket.SOCK_STREAM):
  File "/usr/local/lib/python3.10/socket.py", line 955, in getaddrinfo
    for res in _socket.getaddrinfo(host, port, family, type, proto, flags):
socket.gaierror: [Errno -2] Name or service not known

During handling of the above exception, another exception occurred:

Traceback (most recent call last):
  File "/usr/local/lib/python3.10/site-packages/urllib3/connectionpool.py", line 703, in urlopen
    httplib_response = self._make_request(
  File "/usr/local/lib/python3.10/site-packages/urllib3/connectionpool.py", line 398, in _make_request
    conn.request(method, url, **httplib_request_kw)
  File "/usr/local/lib/python3.10/site-packages/urllib3/connection.py", line 239, in request
    super(HTTPConnection, self).request(method, url, body=body, headers=headers)
  File "/usr/local/lib/python3.10/http/client.py", line 1282, in request
    self._send_request(method, url, body, headers, encode_chunked)
  File "/usr/local/lib/python3.10/http/client.py", line 1328, in _send_request
    self.endheaders(body, encode_chunked=encode_chunked)
  File "/usr/local/lib/python3.10/http/client.py", line 1277, in endheaders
    self._send_output(message_body, encode_chunked=encode_chunked)
  File "/usr/local/lib/python3.10/http/client.py", line 1037, in _send_output
    self.send(msg)
  File "/usr/local/lib/python3.10/http/client.py", line 975, in send
    self.connect()
  File "/usr/local/lib/python3.10/site-packages/urllib3/connection.py", line 205, in connect
    conn = self._new_conn()
  File "/usr/local/lib/python3.10/site-packages/urllib3/connection.py", line 186, in _new_conn
    raise NewConnectionError(
urllib3.exceptions.NewConnectionError: <urllib3.connection.HTTPConnection object at 0x7f9f3b56bdc0>: Failed to establish a new connection: [Errno -2] Name or service not known

During handling of the above exception, another exception occurred:

Traceback (most recent call last):
  File "/usr/local/lib/python3.10/site-packages/requests/adapters.py", line 440, in send
    resp = conn.urlopen(
  File "/usr/local/lib/python3.10/site-packages/urllib3/connectionpool.py", line 787, in urlopen
    retries = retries.increment(
  File "/usr/local/lib/python3.10/site-packages/urllib3/util/retry.py", line 592, in increment
    raise MaxRetryError(_pool, url, error or ResponseError(cause))
urllib3.exceptions.MaxRetryError: HTTPConnectionPool(host='open.egov.kz', port=80): Max retries exceeded with url: /proxy2/culs_payments?token=1af98c4aed474b6199ea44db15ee303c (Caused by NewConnectionError('<urllib3.connection.HTTPConnection object at 0x7f9f3b56bdc0>: Failed to establish a new connection: [Errno -2] Name or service not known'))

During handling of the above exception, another exception occurred:

Traceback (most recent call last):
  File "/usr/local/lib/python3.10/site-packages/uvicorn/protocols/http/httptools_impl.py", line 372, in run_asgi
    result = await app(self.scope, self.receive, self.send)
  File "/usr/local/lib/python3.10/site-packages/uvicorn/middleware/proxy_headers.py", line 75, in __call__
    return await self.app(scope, receive, send)
  File "/usr/local/lib/python3.10/site-packages/fastapi/applications.py", line 261, in __call__
    await super().__call__(scope, receive, send)
  File "/usr/local/lib/python3.10/site-packages/starlette/applications.py", line 112, in __call__
    await self.middleware_stack(scope, receive, send)
  File "/usr/local/lib/python3.10/site-packages/starlette/middleware/errors.py", line 181, in __call__
    raise exc
  File "/usr/local/lib/python3.10/site-packages/starlette/middleware/errors.py", line 159, in __call__
    await self.app(scope, receive, _send)
  File "/usr/local/lib/python3.10/site-packages/starlette/middleware/cors.py", line 84, in __call__
    await self.app(scope, receive, send)
  File "/usr/local/lib/python3.10/site-packages/starlette/exceptions.py", line 82, in __call__
    raise exc
  File "/usr/local/lib/python3.10/site-packages/starlette/exceptions.py", line 71, in __call__
    await self.app(scope, receive, sender)
  File "/usr/local/lib/python3.10/site-packages/fastapi/middleware/asyncexitstack.py", line 21, in __call__
    raise e
  File "/usr/local/lib/python3.10/site-packages/fastapi/middleware/asyncexitstack.py", line 18, in __call__
    await self.app(scope, receive, send)
  File "/usr/local/lib/python3.10/site-packages/starlette/routing.py", line 656, in __call__
    await route.handle(scope, receive, send)
  File "/usr/local/lib/python3.10/site-packages/starlette/routing.py", line 259, in handle
    await self.app(scope, receive, send)
  File "/usr/local/lib/python3.10/site-packages/starlette/routing.py", line 61, in app
    response = await func(request)
  File "/usr/local/lib/python3.10/site-packages/fastapi/routing.py", line 227, in app
    raw_response = await run_endpoint_function(
  File "/usr/local/lib/python3.10/site-packages/fastapi/routing.py", line 162, in run_endpoint_function
    return await run_in_threadpool(dependant.call, **values)
  File "/usr/local/lib/python3.10/site-packages/starlette/concurrency.py", line 39, in run_in_threadpool
    return await anyio.to_thread.run_sync(func, *args)
  File "/usr/local/lib/python3.10/site-packages/anyio/to_thread.py", line 31, in run_sync
    return await get_asynclib().run_sync_in_worker_thread(
  File "/usr/local/lib/python3.10/site-packages/anyio/_backends/_asyncio.py", line 937, in run_sync_in_worker_thread
    return await future
  File "/usr/local/lib/python3.10/site-packages/anyio/_backends/_asyncio.py", line 867, in run
    result = context.run(func, *args)
  File "/home/api_app/./main.py", line 70, in api_payments
    return api_payments_parser(bin, start_date,)
  File "/home/api_app/./parsers/api_payments_parser.py", line 23, in api_payments_parser
    response = request("POST", url, headers=headers, data=payload)
  File "/usr/local/lib/python3.10/site-packages/requests/api.py", line 61, in request
    return session.request(method=method, url=url, **kwargs)
  File "/usr/local/lib/python3.10/site-packages/requests/sessions.py", line 529, in request
    resp = self.send(prep, **send_kwargs)
  File "/usr/local/lib/python3.10/site-packages/requests/sessions.py", line 645, in send
    r = adapter.send(request, **kwargs)
  File "/usr/local/lib/python3.10/site-packages/requests/adapters.py", line 519, in send
    raise ConnectionError(e, request=request)
requests.exceptions.ConnectionError: HTTPConnectionPool(host='open.egov.kz', port=80): Max retries exceeded with url: /proxy2/culs_payments?token=1af98c4aed474b6199ea44db15ee303c (Caused by NewConnectionError('<urllib3.connection.HTTPConnection object at 0x7f9f3b56bdc0>: Failed to establish a new connection: [Errno -2] Name or service not known'))
10:54:13 - INFO -172.19.0.19:58270 - "GET /api_goszakup?iin_bin=170340012106 HTTP/1.1" 500 (httptools_impl.py:437)
10:54:13 - ERROR -Exception in ASGI application
 (httptools_impl.py:375)
Traceback (most recent call last):
  File "/usr/local/lib/python3.10/site-packages/urllib3/connection.py", line 174, in _new_conn
    conn = connection.create_connection(
  File "/usr/local/lib/python3.10/site-packages/urllib3/util/connection.py", line 72, in create_connection
    for res in socket.getaddrinfo(host, port, family, socket.SOCK_STREAM):
  File "/usr/local/lib/python3.10/socket.py", line 955, in getaddrinfo
    for res in _socket.getaddrinfo(host, port, family, type, proto, flags):
socket.gaierror: [Errno -2] Name or service not known

During handling of the above exception, another exception occurred:

Traceback (most recent call last):
  File "/usr/local/lib/python3.10/site-packages/urllib3/connectionpool.py", line 703, in urlopen
    httplib_response = self._make_request(
  File "/usr/local/lib/python3.10/site-packages/urllib3/connectionpool.py", line 386, in _make_request
    self._validate_conn(conn)
  File "/usr/local/lib/python3.10/site-packages/urllib3/connectionpool.py", line 1042, in _validate_conn
    conn.connect()
  File "/usr/local/lib/python3.10/site-packages/urllib3/connection.py", line 358, in connect
    self.sock = conn = self._new_conn()
  File "/usr/local/lib/python3.10/site-packages/urllib3/connection.py", line 186, in _new_conn
    raise NewConnectionError(
urllib3.exceptions.NewConnectionError: <urllib3.connection.HTTPSConnection object at 0x7f9f3b56b970>: Failed to establish a new connection: [Errno -2] Name or service not known

During handling of the above exception, another exception occurred:

Traceback (most recent call last):
  File "/usr/local/lib/python3.10/site-packages/requests/adapters.py", line 440, in send
    resp = conn.urlopen(
  File "/usr/local/lib/python3.10/site-packages/urllib3/connectionpool.py", line 787, in urlopen
    retries = retries.increment(
  File "/usr/local/lib/python3.10/site-packages/urllib3/util/retry.py", line 592, in increment
    raise MaxRetryError(_pool, url, error or ResponseError(cause))
urllib3.exceptions.MaxRetryError: HTTPSConnectionPool(host='ows.goszakup.gov.kz', port=443): Max retries exceeded with url: /v3/subject/biin/170340012106 (Caused by NewConnectionError('<urllib3.connection.HTTPSConnection object at 0x7f9f3b56b970>: Failed to establish a new connection: [Errno -2] Name or service not known'))

During handling of the above exception, another exception occurred:

Traceback (most recent call last):
  File "/usr/local/lib/python3.10/site-packages/uvicorn/protocols/http/httptools_impl.py", line 372, in run_asgi
    result = await app(self.scope, self.receive, self.send)
  File "/usr/local/lib/python3.10/site-packages/uvicorn/middleware/proxy_headers.py", line 75, in __call__
    return await self.app(scope, receive, send)
  File "/usr/local/lib/python3.10/site-packages/fastapi/applications.py", line 261, in __call__
    await super().__call__(scope, receive, send)
  File "/usr/local/lib/python3.10/site-packages/starlette/applications.py", line 112, in __call__
    await self.middleware_stack(scope, receive, send)
  File "/usr/local/lib/python3.10/site-packages/starlette/middleware/errors.py", line 181, in __call__
    raise exc
  File "/usr/local/lib/python3.10/site-packages/starlette/middleware/errors.py", line 159, in __call__
    await self.app(scope, receive, _send)
  File "/usr/local/lib/python3.10/site-packages/starlette/middleware/cors.py", line 84, in __call__
    await self.app(scope, receive, send)
  File "/usr/local/lib/python3.10/site-packages/starlette/exceptions.py", line 82, in __call__
    raise exc
  File "/usr/local/lib/python3.10/site-packages/starlette/exceptions.py", line 71, in __call__
    await self.app(scope, receive, sender)
  File "/usr/local/lib/python3.10/site-packages/fastapi/middleware/asyncexitstack.py", line 21, in __call__
    raise e
  File "/usr/local/lib/python3.10/site-packages/fastapi/middleware/asyncexitstack.py", line 18, in __call__
    await self.app(scope, receive, send)
  File "/usr/local/lib/python3.10/site-packages/starlette/routing.py", line 656, in __call__
    await route.handle(scope, receive, send)
  File "/usr/local/lib/python3.10/site-packages/starlette/routing.py", line 259, in handle
    await self.app(scope, receive, send)
  File "/usr/local/lib/python3.10/site-packages/starlette/routing.py", line 61, in app
    response = await func(request)
  File "/usr/local/lib/python3.10/site-packages/fastapi/routing.py", line 227, in app
    raw_response = await run_endpoint_function(
  File "/usr/local/lib/python3.10/site-packages/fastapi/routing.py", line 162, in run_endpoint_function
    return await run_in_threadpool(dependant.call, **values)
  File "/usr/local/lib/python3.10/site-packages/starlette/concurrency.py", line 39, in run_in_threadpool
    return await anyio.to_thread.run_sync(func, *args)
  File "/usr/local/lib/python3.10/site-packages/anyio/to_thread.py", line 31, in run_sync
    return await get_asynclib().run_sync_in_worker_thread(
  File "/usr/local/lib/python3.10/site-packages/anyio/_backends/_asyncio.py", line 937, in run_sync_in_worker_thread
    return await future
  File "/usr/local/lib/python3.10/site-packages/anyio/_backends/_asyncio.py", line 867, in run
    result = context.run(func, *args)
  File "/home/api_app/./main.py", line 55, in api_goszakup
    return parse_participant(iin_bin)
  File "/home/api_app/./parsers/api_goszakup_parser.py", line 12, in parse_participant
    response = request("GET", url, headers=headers, data={}, verify=False)
  File "/usr/local/lib/python3.10/site-packages/requests/api.py", line 61, in request
    return session.request(method=method, url=url, **kwargs)
  File "/usr/local/lib/python3.10/site-packages/requests/sessions.py", line 529, in request
    resp = self.send(prep, **send_kwargs)
  File "/usr/local/lib/python3.10/site-packages/requests/sessions.py", line 645, in send
    r = adapter.send(request, **kwargs)
  File "/usr/local/lib/python3.10/site-packages/requests/adapters.py", line 519, in send
    raise ConnectionError(e, request=request)
requests.exceptions.ConnectionError: HTTPSConnectionPool(host='ows.goszakup.gov.kz', port=443): Max retries exceeded with url: /v3/subject/biin/170340012106 (Caused by NewConnectionError('<urllib3.connection.HTTPSConnection object at 0x7f9f3b56b970>: Failed to establish a new connection: [Errno -2] Name or service not known'))
10:54:13 - INFO -172.19.0.19:58282 - "GET /api_goszakup_unrelaible?iin_bin=170340012106 HTTP/1.1" 500 (httptools_impl.py:437)
10:54:13 - ERROR -Exception in ASGI application
 (httptools_impl.py:375)
Traceback (most recent call last):
  File "/usr/local/lib/python3.10/site-packages/urllib3/connection.py", line 174, in _new_conn
    conn = connection.create_connection(
  File "/usr/local/lib/python3.10/site-packages/urllib3/util/connection.py", line 72, in create_connection
    for res in socket.getaddrinfo(host, port, family, socket.SOCK_STREAM):
  File "/usr/local/lib/python3.10/socket.py", line 955, in getaddrinfo
    for res in _socket.getaddrinfo(host, port, family, type, proto, flags):
socket.gaierror: [Errno -2] Name or service not known

During handling of the above exception, another exception occurred:

Traceback (most recent call last):
  File "/usr/local/lib/python3.10/site-packages/urllib3/connectionpool.py", line 703, in urlopen
    httplib_response = self._make_request(
  File "/usr/local/lib/python3.10/site-packages/urllib3/connectionpool.py", line 398, in _make_request
    conn.request(method, url, **httplib_request_kw)
  File "/usr/local/lib/python3.10/site-packages/urllib3/connection.py", line 239, in request
    super(HTTPConnection, self).request(method, url, body=body, headers=headers)
  File "/usr/local/lib/python3.10/http/client.py", line 1282, in request
    self._send_request(method, url, body, headers, encode_chunked)
  File "/usr/local/lib/python3.10/http/client.py", line 1328, in _send_request
    self.endheaders(body, encode_chunked=encode_chunked)
  File "/usr/local/lib/python3.10/http/client.py", line 1277, in endheaders
    self._send_output(message_body, encode_chunked=encode_chunked)
  File "/usr/local/lib/python3.10/http/client.py", line 1037, in _send_output
    self.send(msg)
  File "/usr/local/lib/python3.10/http/client.py", line 975, in send
    self.connect()
  File "/usr/local/lib/python3.10/site-packages/urllib3/connection.py", line 205, in connect
    conn = self._new_conn()
  File "/usr/local/lib/python3.10/site-packages/urllib3/connection.py", line 186, in _new_conn
    raise NewConnectionError(
urllib3.exceptions.NewConnectionError: <urllib3.connection.HTTPConnection object at 0x7f9f3b569a80>: Failed to establish a new connection: [Errno -2] Name or service not known

During handling of the above exception, another exception occurred:

Traceback (most recent call last):
  File "/usr/local/lib/python3.10/site-packages/requests/adapters.py", line 440, in send
    resp = conn.urlopen(
  File "/usr/local/lib/python3.10/site-packages/urllib3/connectionpool.py", line 787, in urlopen
    retries = retries.increment(
  File "/usr/local/lib/python3.10/site-packages/urllib3/util/retry.py", line 592, in increment
    raise MaxRetryError(_pool, url, error or ResponseError(cause))
urllib3.exceptions.MaxRetryError: HTTPConnectionPool(host='ows.goszakup.gov.kz', port=80): Max retries exceeded with url: /v3/rnu/170340012106 (Caused by NewConnectionError('<urllib3.connection.HTTPConnection object at 0x7f9f3b569a80>: Failed to establish a new connection: [Errno -2] Name or service not known'))

During handling of the above exception, another exception occurred:

Traceback (most recent call last):
  File "/usr/local/lib/python3.10/site-packages/uvicorn/protocols/http/httptools_impl.py", line 372, in run_asgi
    result = await app(self.scope, self.receive, self.send)
  File "/usr/local/lib/python3.10/site-packages/uvicorn/middleware/proxy_headers.py", line 75, in __call__
    return await self.app(scope, receive, send)
  File "/usr/local/lib/python3.10/site-packages/fastapi/applications.py", line 261, in __call__
    await super().__call__(scope, receive, send)
  File "/usr/local/lib/python3.10/site-packages/starlette/applications.py", line 112, in __call__
    await self.middleware_stack(scope, receive, send)
  File "/usr/local/lib/python3.10/site-packages/starlette/middleware/errors.py", line 181, in __call__
    raise exc
  File "/usr/local/lib/python3.10/site-packages/starlette/middleware/errors.py", line 159, in __call__
    await self.app(scope, receive, _send)
  File "/usr/local/lib/python3.10/site-packages/starlette/middleware/cors.py", line 84, in __call__
    await self.app(scope, receive, send)
  File "/usr/local/lib/python3.10/site-packages/starlette/exceptions.py", line 82, in __call__
    raise exc
  File "/usr/local/lib/python3.10/site-packages/starlette/exceptions.py", line 71, in __call__
    await self.app(scope, receive, sender)
  File "/usr/local/lib/python3.10/site-packages/fastapi/middleware/asyncexitstack.py", line 21, in __call__
    raise e
  File "/usr/local/lib/python3.10/site-packages/fastapi/middleware/asyncexitstack.py", line 18, in __call__
    await self.app(scope, receive, send)
  File "/usr/local/lib/python3.10/site-packages/starlette/routing.py", line 656, in __call__
    await route.handle(scope, receive, send)
  File "/usr/local/lib/python3.10/site-packages/starlette/routing.py", line 259, in handle
    await self.app(scope, receive, send)
  File "/usr/local/lib/python3.10/site-packages/starlette/routing.py", line 61, in app
    response = await func(request)
  File "/usr/local/lib/python3.10/site-packages/fastapi/routing.py", line 227, in app
    raw_response = await run_endpoint_function(
  File "/usr/local/lib/python3.10/site-packages/fastapi/routing.py", line 162, in run_endpoint_function
    return await run_in_threadpool(dependant.call, **values)
  File "/usr/local/lib/python3.10/site-packages/starlette/concurrency.py", line 39, in run_in_threadpool
    return await anyio.to_thread.run_sync(func, *args)
  File "/usr/local/lib/python3.10/site-packages/anyio/to_thread.py", line 31, in run_sync
    return await get_asynclib().run_sync_in_worker_thread(
  File "/usr/local/lib/python3.10/site-packages/anyio/_backends/_asyncio.py", line 937, in run_sync_in_worker_thread
    return await future
  File "/usr/local/lib/python3.10/site-packages/anyio/_backends/_asyncio.py", line 867, in run
    result = context.run(func, *args)
  File "/home/api_app/./main.py", line 62, in api_goszakup_unrelaible
    return parse_unrelaible_participant(iin_bin)
  File "/home/api_app/./parsers/api_goszakup_parser.py", line 25, in parse_unrelaible_participant
    response = request("GET", url, headers=headers, data={}, verify=False)
  File "/usr/local/lib/python3.10/site-packages/requests/api.py", line 61, in request
    return session.request(method=method, url=url, **kwargs)
  File "/usr/local/lib/python3.10/site-packages/requests/sessions.py", line 529, in request
    resp = self.send(prep, **send_kwargs)
  File "/usr/local/lib/python3.10/site-packages/requests/sessions.py", line 645, in send
    r = adapter.send(request, **kwargs)
  File "/usr/local/lib/python3.10/site-packages/requests/adapters.py", line 519, in send
    raise ConnectionError(e, request=request)
requests.exceptions.ConnectionError: HTTPConnectionPool(host='ows.goszakup.gov.kz', port=80): Max retries exceeded with url: /v3/rnu/170340012106 (Caused by NewConnectionError('<urllib3.connection.HTTPConnection object at 0x7f9f3b569a80>: Failed to establish a new connection: [Errno -2] Name or service not known'))
